# Issue v0.4.14: `open_directory`ツールの堅牢性向上

## 経緯
`/rag`コマンドのワークフロー実行テスト中、最終ステップで呼び出される`open_directory`ツールが、特定の条件下でエラー終了（exit code 1）することが判明しました。

## 現状の問題点
Windows環境において、`open_directory`ツールが開こうとするディレクトリが既にエクスプローラーで開かれている場合、`explorer.exe`コマンドが非ゼロの終了コードを返すことがあります。

現在の`open_directory.py`の実装では、`subprocess.run`を`check=True`で呼び出しているため、この非ゼロの終了コードを検知して`CalledProcessError`例外が発生し、ツールが異常終了してしまいます。

AIエージェントはツールの異常終了をワークフローの失敗と見なすため、本来は成功しているにも関わらず、最後の最後で処理が失敗したと判断されてしまいます。

## 解決策の概要
`open_directory.py`を修正し、`subprocess.run`呼び出し時の`check`引数を`False`に変更します。

## 解決策の詳細
1.  **`src/ragmaker/tools/open_directory.py` の修正**:
    -   `subprocess.run(command, check=True)`となっている箇所を`subprocess.run(command, check=False)`に修正します。
    -   これにより、OSのファイルマネージャーがどのような終了コードを返しても、ツール自体は常に正常終了（exit code 0）するようになります。
    -   このツールはユーザーの利便性を高めるためのものであり、その成否がワークフロー全体の成否に影響を与えるべきではないため、この変更は妥当です。

```diff
--- a/src/ragmaker/tools/open_directory.py
+++ b/src/ragmaker/tools/open_directory.py
@@ -34,7 +34,10 @@
         elif sys.platform == "darwin":  # macOS
             command = ["open", directory_path]
         else:  # Linux and other POSIX
             command = ["xdg-open", directory_path]
-        subprocess.run(command, check=True)
+
+        # check=False ensures that the script doesn't raise an exception
+        # even if the command returns a non-zero exit code (e.g., on Windows
+        # when the folder is already open).
+        subprocess.run(command, check=False)
 
         print_json_stdout({
             "status": "success",
```

## テスト方法
1.  Windows環境で、ナレッジベースのディレクトリを手動でエクスプローラーで開いておきます。
2.  `/rag`コマンドのワークフローを最後まで実行します。
3.  最終ステップで`open_directory`ツールが呼び出された際に、エラーが発生せず、ワークフローが正常に完了することを確認します。