# Issue v0.4.1.1: Fix: Resolve GitPython file lock issue in tests on Windows

## 前提知識
- `test/test_github_fetch.py`
- `GitPython` ライブラリの挙動
- Windowsにおけるファイルロックの仕様

## 経緯
v0.4.1のリファクタリング完了後、再テストを実施したところ、`test_github_fetch.py` の単体テストがWindows環境で失敗した。

## 現状の問題点
テストログを分析した結果、テスト終了後のクリーンアップ処理（`tearDown`メソッド）において `PermissionError: [WinError 32] プロセスはファイルにアクセスできません。` が発生していることが判明した。

これは、テスト準備段階（`setUp`メソッド）で `git.Repo.init()` によって作成されたリポジトリのファイル（特に`.git`ディレクトリ内のファイル）が、`GitPython`ライブラリによってロックされたままになるためである。
テスト終了時に`TemporaryDirectory.cleanup()`がディレクトリを削除しようとしても、ファイルロックが解放されていないため、Windows OSが削除を拒否し、テストが失敗する。これは特にWindowsで顕著なファイルハンドルの問題である。

## 解決策の概要
テスト終了時に、ディレクトリのクリーンアップ処理を行う前に、`GitPython`が保持しているリポジトリのリソースを明示的に解放する。

## 解決策の詳細
1.  `test/test_github_fetch.py` の `setUp` メソッドを修正し、初期化した `Repo` オブジェクトをインスタンス変数（例: `self.repo`）に格納する。
2.  `tearDown` メソッドを修正し、`self.test_dir.cleanup()` を呼び出す直前に `self.repo.close()` を実行する。これにより、ファイルハンドルが解放され、一時ディレクトリを安全に削除できるようになる。

## 参考とすべきスクリプト等
- `test/test_github_fetch.py`

## テスト方法
`test_github_fetch.py` を含む単体テストスイートをWindows環境で実行し、`PermissionError` が発生せずにすべてのテストがパスすることを確認する。

## 実装状況
テストがパスし、v0.4.1.1としてリリース。

### コミットメッセージ

```
Fix(test): Resolve GitPython file lock issue on Windows

The `test_github_fetch` unit test was failing on Windows with a
`PermissionError` during the `tearDown` phase. This was caused by
GitPython holding a lock on files within the temporary .git directory,
preventing the `TemporaryDirectory.cleanup()` call from successfully
deleting the directory.

This commit resolves the issue by explicitly closing the GitPython `Repo`
object in the `tearDown` method before the cleanup is performed.
This ensures that all file handles are released, allowing the test
to complete successfully on Windows.

Changes:
- Modified `test/test_github_fetch.py` to store the `Repo` object as an
  instance variable and call `repo.close()` in `tearDown`.
```